Workbook

Sheet Introduction

Sheet Sources
A1: Bases and Sources of the data/assumption used in the valuation.
A3: Sl. No. | B3: Detail of Assumption/Data point | C3: Assumed Figure | D3: Remarks | E3: URL
A4: 1 | B4: Actual Financial Statement data for last 5 years | C4: - | D4: Financial statements has been taken for the last five years from capitaline database | E4: https://awsone.capitaline.com/index.html#/Company/Condensed/condensed?section=ProfitLoss
A5: 2 | B5: Revenue Growth | D5: PowerGrid operates under regulated transmission returns (CERC), resulting in stable mid-single-digit revenue growth aligned with asset base expansion and capex cycle. | E5: https://awsone.capitaline.com/index.html#/Company/Condensed/condensed?section=ProfitLoss
A6: 3 | B6: Tax Rate | C6: 0.1955 | D6: Effective tax rate is taken from the company’s most recent annual financial statement to reflect actual tax burden instead of statutory rate. | E6: https://www.powergrid.in/annual-reports
A7: 3 | B7: Data period used for Stock and Market Index Price | C7: - | D7: 7 years daily price changes of BSE Sensex and Tata Steel Ltd. has been used to calculate Beta. | E7: https://www.nseindia.com/get-quotes/equity?symbol=POWERGRID
A8: 4 | B8: Risk Free Rate | C8: 0.0667 | D8: 10-year government bond yield is used as proxy for long-term risk-free rate in valuation models like CAPM and DDM. | E8: https://in.investing.com/rates-bonds/india-10-year-bond-yield
A9: 5 | B9: Market Risk Premium | C9: 0.0685 | D9: Equity Risk Premium for India is taken from Damodaran’s dataset, widely accepted in academic and professional valuation practice. | E9: https://www.indigrid.co.in/wp-content/uploads/2025/07/Valuation.pdf
A10: 6 | B10: Perpetuity Growth Rate for Terminal Value | C10: 0.055 | E10: https://images.assettype.com/bloombergquint/2021-06/a25d87d1-ef19-46d2-93c3-eb995c94e641/Motilal_Oswal_Power_Grid_Q4FY21_Result_Update.pdf
A11: 7 | B11: Basis for selection of peer companies | D11: forn screener | E11: https://www.screener.in/company/POWERGRID/consolidated/#peers
A12: 8 | B12: Sensitivity Analysis
A13: 9 | B13: Peer Comparison
A14: 10 | B14: company essentials | E14: https://ticker.finology.in/company/POWERGRID
A15: 11 | B15: Depreciation rate | C15: 0.07 | D15: as listed by CERC (Central Electricity Regulatory Commission) | E15: https://powermin.gov.in/en/content/depreciation-norms-generating-companies

Sheet Industry analysis
A1: INDUSTRY ANALYSIS
A3: Industry Nature | K3: Growth Drivers
A4: The power transmission industry in India operates as a regulated utility sector, meaning: Returns are determined by regulatory bodies like CERC (Central Electricity Regulatory Commission) Companies earn a fixed return on capital (RoE model) rather than market-based pricing Key features: Natural monopoly: Transmission networks require huge infrastructure and cannot be duplicated easily Low competition: Dominated by a few players like Power Grid Corporation of India Adani Energy Solutions Long asset life: Transmission assets (lines, substations) last 25–35 years 👉 This makes the industry stable, predictable, and infrastructure-driven. | K4: 1. Renewable Energy Expansion 3. Green Energy Corridors India targets 500 GW renewable capacity by 2030 Dedicated transmission systems for renewable energy Solar and wind projects are often located in remote areas Reduces power loss and improves efficiency Requires strong transmission networks to connect: Generation locations → consumption centers 2. Inter-State Transmission Development 4. Electrification & Demand Growth Power needs to flow across states efficiently Rural electrification Government is building National Grid integration Industrial expansion Increases demand for: EV charging infrastructure High-voltage transmission lines All increase dependency on transmission networks Grid connectivity projects REVENUE MODEL Not dependent on: Power prices, Demand fluctuations, Commodity cycles
A20: Industry Risks
A21: 1. Regulatory Risk 4. Policy Risk Changes in tariff rules or allowed returns Changes in renewable policies Delay in approvals Shift in government priorities 2. Execution Risk 5. Technological Risk (Emerging) Delays in project completion Smart grids Land acquisition issues Energy storage Environmental clearances Decentralized power generation May change future transmission requirements 3. Interest Rate Risk Sector is debt-heavy Rising rates → higher financing cost
K22: The Indian power transmission industry is a highly regulated, capital-intensive sector characterized by stable and predictable returns, low competition, and strong entry barriers. Growth is primarily driven by renewable energy expansion, inter-state connectivity, and increasing electricity demand. Despite risks related to regulation and project execution, the sector remains fundamentally strong and well-positioned for long-term growth, making it attractive for valuation using stable cash flow-based models.

Sheet About Company
A1: POWERGRID CORPORATION OF INDIA LTD.
A3: ABOUT THE COMPANY | E3: BUSINESS SEGMENTS OF POWERGRID | I3: ESG & SUSTAINABILITY - POWERGRID CORPORATION OF INDIA LTD.
A4: Particulars | B4: Details | E4: Segment | F4: Key Activities | G4: Business Description | I4: ESG Pillar | J4: Key Focus Area | K4: Description | L4: Valuation Significance
A5: Company Name | B5: Power Grid Corporation of India Ltd | E5: Transmission Services | F5: Interstate Transmission System (ISTS), UHVAC / HVDC networks | G5: Core revenue contributor. Develops, operates, and maintains India’s national electricity transmission grid under regulated tariff framework. | I5: Environmental (E) | J5: Renewable Energy Integration | K5: Develops transmission infrastructure for solar and wind evacuation under Green Energy Corridor projects. | L5: Supports long-term asset growth and aligns with India’s clean energy transition.
A6: Listing | B6: NSE / BSE | E6: Telecom Business | F6: PowerTel, Fiber Optic Network | G6: Leverages transmission infrastructure to provide telecom and bandwidth services across India. | J6: Low Direct Carbon Footprint | K6: As a transmission utility (not a generator), operational emissions are comparatively low. | L6: Enhances ESG profile and attracts sustainability-focused investors.
A7: Sector | B7: Utilities | E7: Consultancy & Project Management | F7: Engineering, Procurement, Construction (EPC), consultancy services | G7: Provides consultancy and turnkey project services in domestic and international markets. | J7: Grid Efficiency & Loss Reduction | K7: Advanced grid automation reduces transmission losses and improves efficiency. | L7: Improves operating performance and margin stability.
A8: Industry | B8: Power Transmission (Energy Infrastructure) | E8: Smart Grid & Emerging Technologies | F8: Smart metering, grid automation, renewable integration | G8: Focused on digital grid modernization, renewable evacuation infrastructure, and energy transition initiatives. | J8: Sustainable Infrastructure Development | K8: Focus on environmentally responsible project execution and land management. | L8: Reduces regulatory and environmental compliance risk.
A9: Founded | B9: 1989 | J9: Climate Resilience | K9: Investments in smart grid and system strengthening to manage climate-related risks. | L9: Enhances long-term asset durability and earnings visibility.
A10: Headquarters | B10: Gurugram, Haryana, India | I10: Social (S) | J10: National Infrastructure Backbone | K10: Ensures reliable electricity transmission across India, supporting industrial and rural development. | L10: Strengthens strategic importance and demand stability.
A11: Promoter / Parent | B11: Government of India | E11: GROWTH DRIVERS- POWERGRID CORPORATION OF INDIA LTD. | J11: Employee Safety & Training | K11: Strong safety protocols and technical training for high-voltage operations. | L11: Reduces operational disruptions and accident-related liabilities.
A12: Market Cap | B12: ~₹2.5–3 Trillion (Approx., update with latest) | E12: Growth Driver | F12: Explanation | G12: Valuation Significance | J12: CSR & Community Development | K12: Active involvement in healthcare, education, and community upliftment initiatives. | L12: Enhances brand credibility and stakeholder trust.
E13: Expansion in Renewable Energy Capacity | F13: Government push toward solar and wind energy requires new transmission lines for evacuation. | G13: Supports long-term asset base growth and revenue visibility. | J13: Stakeholder Engagement | K13: Close coordination with regulators, state utilities, and policymakers. | L13: Improves regulatory alignment and reduces policy risk.
A14: Power Grid Corporation of India Ltd represents a structurally stable play on India’s power transmission infrastructure growth. As a regulated utility with nationwide grid presence, the company benefits from predictable tariff-based returns and long-term government-backed capital expenditure programs. The expansion of renewable energy capacity, grid modernization, and cross-border interconnections provide sustained asset base growth. However, earnings remain dependent on regulatory frameworks, capital expenditure cycles, and timely project execution. | E14: National Grid Strengthening & Capex Pipeline | F14: Continuous investments in interstate and cross-border transmission projects. | G14: Drives regulated asset growth and stable earnings expansion. | I14: Governance (G) | J14: Government Ownership | K14: Majority stake held by Government of India ensures strategic backing. | L14: Lowers credit risk and reduces cost of capital.
E15: Regulated Return Model (CERC Framework) | F15: Fixed return on equity under tariff regulations reduces volatility. | G15: Enhances earnings predictability and lowers risk premium. | J15: Regulated Tariff Framework (CERC) | K15: Transparent return on equity model ensures predictable earnings. | L15: Enhances DCF stability and lowers volatility assumptions.
E16: Green Energy Corridor Projects | F16: Dedicated infrastructure for renewable power evacuation. | G16: Long-term structural growth opportunity. | J16: Strong Compliance & Board Oversight | K16: Adherence to SEBI norms and corporate governance standards. | L16: Builds investor confidence and improves valuation multiples.
E17: Digital & Smart Grid Modernization | F17: Automation, smart meters, real-time monitoring systems. | G17: Improves efficiency and operational leverage. | J17: Asset Monetization (InvIT Route) | K17: Monetization of operational assets to optimize capital structure. | L17: Improves ROE and capital efficiency.
E18: Asset Monetization (InvIT Route) | F18: Monetization of operational assets via Infrastructure Investment Trusts. | G18: Improves capital efficiency and supports higher ROE. | J18: High Credit Ratings | K18: Strong financial discipline and governance credibility. | L18: Supports lower borrowing cost and WACC.
E19: Strong Government Backing | F19: Majority ownership by Government of India ensures strategic importance. | G19: Reduces credit risk and supports lower cost of capital.
A23: Economic Moat – PowerGrid Corporation of India Ltd
A24: PowerGrid possesses a strong economic moat driven by its nationwide transmission network, regulatory entry barriers, and government ownership. The company operates critical national infrastructure under a regulated return framework, limiting competitive threats. High capital requirements and technical expertise create significant barriers to entry. Long asset life cycles and assured tariff-based revenues provide durable cash flows. Additionally, its leadership in renewable energy evacuation and grid modernization strengthens its strategic importance in India’s energy transition, supporting long-term earnings visibility.
B30: Company Essentials
B32: Market Cap | E32: Enterprise Value | G32: No. of Shares
B33: ₹ 2,80,692.22 Cr. | E33: ₹ 4,05,237.78 Cr. | G33: 930.06 Cr.
B35: P/E | E35: P/B | G35: Face Value
B36: 19.15 | E36: 2.74 | G36: 10
B38: Div. Yield | E38: Book Value (TTM) | G38: CASH
B39: 0.0293 | E39: ₹ 110.10 | G39: ₹ 6,419.40 Cr.
F59: DEBT
F60: ₹ 1,30,964.96 Cr.
F62: Promoter Holding
F63: 0.5134
F65: EPS (TTM)
F66: ₹ 15.76
F68: Sales Growth
F69: -0.0226
F71: ROE
F72: 17.15 %
F74: ROCE
F75: 0.1296
F77: Profit Growth
...

Sheet Economic analysis
A1: ECONOMIC ANALYSIS
A3: Macroeconomic Environment | K3: Power Demand Outlook
A4: India is currently one of the fastest-growing major economies, with GDP growth expected to remain around 6–7% in the medium term. This growth is supported by strong domestic consumption, infrastructure development, and government initiatives. Economic growth has a direct impact on electricity demand, because: Industries require more power for production Commercial sectors (offices, malls, IT parks) expand Household consumption increases with rising income Therefore, as GDP grows, power demand rises proportionately, creating a strong need for expansion of transmission infrastructure. | K4: India’s electricity demand is expected to grow consistently over the next decade, driven by structural changes in the economy. Key growth drivers: Electric Vehicles (EVs): Increasing adoption will significantly raise electricity consumption Digital Economy: Growth of data centers, cloud computing, and AI infrastructure requires continuous power supply Manufacturing Push: Government initiatives like Make in India and PLI schemes are boosting industrial activity Urbanization: Expansion of cities increases residential and commercial electricity demand These factors will require a robust and efficient transmission network to transport electricity across regions.
A18: Interest Rate and Inflation | K18: Government Policies & Support
A19: The power sector, especially transmission, is highly capital-intensive, meaning: Companies rely heavily on debt financing Large investments are required for infrastructure projects Impact: Rising interest rates → increase borrowing costs → may reduce profitability Inflation → increases project costs (materials, labor) However, for companies like PowerGrid: Returns are regulated by government (RoE-based model) This provides stability and protection against cost fluctuations So even in a high-interest environment, earnings remain relatively stable. | K19: The Indian government plays a crucial role in the power sector, especially transmission. Key initiatives: National Electricity Plan: Focus on strengthening grid infrastructure Renewable Energy Target: 500 GW capacity by 2030 Green Energy Corridors: Dedicated transmission lines for renewable power Power for All & Infrastructure Push Renewable energy (solar/wind) is often located in remote areas, so strong transmission networks are essential to deliver power to demand centers.
A35: The macroeconomic environment in India is highly favorable for the power transmission sector. Strong GDP growth, rising electricity demand, rapid urbanization, and government-led infrastructure initiatives are driving the need for expanded transmission networks. Additionally, policy support and regulated returns provide stability, making the sector well-positioned for long-term sustainable growth.

Sheet Company Beta
A1: COMPANY BETA
A3: Date | B3: SENSEX | C3: POWERGRID_PRICES | D3: MARKET RETURN | E3: FIRM RETURN
A4: 40546 | B4: 20561.05 | C4: 97.95
A5: 40547 | B5: 20498.72 | C5: 98.45 | D5: =LN(B5/B4) -> -0.0030360642 | E5: =LN(C5/C4) -> 0.0050916607 | I5: HISTORICAL BETA | J5: =SLOPE(E5:E3721,D5:D3721) -> 0.63115187
A6: 40548 | B6: 20301.1 | C6: 98.1 | D6: =LN(B6/B5) -> -0.0096873734 | E6: =LN(C6/C5) -> -0.0035614385 | I6: INDUSTRY BETA | J6: =AVERAGE(M11:M14) -> 0.19601637
A7: 40549 | B7: 20184.74 | C7: 98.95 | D7: =LN(B7/B6) -> -0.0057481984 | E7: =LN(C7/C6) -> 0.0086273055 | I7: D/E | J7: 1.42
A8: 40550 | B8: 19691.81 | C8: 97.65 | D8: =LN(B8/B7) -> -0.02472406 | E8: =LN(C8/C7) -> -0.013225015 | I8: TAX RATE | J8: 0.1955
A9: 40553 | B9: 19224.12 | C9: 96.15 | D9: =LN(B9/B8) -> -0.024037073 | E9: =LN(C9/C8) -> -0.015480185 | I9: FUNDAMENTAL BETA | J9: =J6/(1+((1-J8)*J7)) -> 0.09149425
A10: 40554 | B10: 19196.34 | C10: 96.1 | D10: =LN(B10/B9) -> -0.0014461047 | E10: =LN(C10/C9) -> -0.00052015606 | I10: Company | J10: Levered Beta (βL)- PAST 5 YR | K10: Debt/Equity (D/E)- FY25 | L10: Tax Rate (T) | M10: Unlevered Beta
A11: 40555 | B11: 19534.1 | C11: 97.25 | D11: =LN(B11/B10) -> 0.01744202 | E11: =LN(C11/C10) -> 0.011895667 | I11: NHPC Limited | J11: 0.17 | K11: 0.89 | L11: 0.284 | M11: =J11/(1+((1-L11)*K11)) -> 0.10383328
A12: 40556 | B12: 19182.82 | C12: 96.6 | D12: =LN(B12/B11) -> -0.018146569 | E12: =LN(C12/C11) -> -0.0067062413 | I12: NTPC Limited | J12: 0.27 | K12: 1.15 | L12: 0.271 | M12: =J12/(1+((1-L12)*K12)) -> 0.14687084
A13: 40557 | B13: 18860.44 | C13: 97.4 | D13: =LN(B13/B12) -> -0.01694848 | E13: =LN(C13/C12) -> 0.0082474694 | I13: Tata Power Company Limited | J13: 0.28 | K13: 1.09 | L13: 0.244 | M13: =J13/(1+((1-L13)*K13)) -> 0.15350541
A14: 40560 | B14: 18882.25 | C14: 97.7 | D14: =LN(B14/B13) -> 0.0011557206 | E14: =LN(C14/C13) -> 0.0030753484 | I14: Adani Energy Solutions Ltd | J14: 0.52 | K14: 0.43 | L14: 0.142 | M14: =J14/(1+((1-L14)*K14)) -> 0.37985595
A15: 40561 | B15: 19092.05 | C15: 98.4 | D15: =LN(B15/B14) -> 0.011049691 | E15: =LN(C15/C14) -> 0.007139245
A16: 40562 | B16: 18978.32 | C16: 97.75 | D16: =LN(B16/B15) -> -0.005974743 | E16: =LN(C16/C15) -> -0.0066276052 | I16: YEAR | J16: 2025 | K16: 2024 | L16: 2023 | M16: 2022 | N16: 2021 | O16: 2020
A17: 40563 | B17: 19046.54 | C17: 98.55 | D17: =LN(B17/B16) -> 0.0035881827 | E17: =LN(C17/C16) -> 0.0081508347 | I17: PAT | J17: 15354 | K17: 15475 | L17: 15333 | M17: 17094 | N17: 11936 | O17: 10811
A18: 40564 | B18: 19007.53 | C18: 98.6 | D18: =LN(B18/B17) -> -0.0020502413 | E18: =LN(C18/C17) -> 0.00050722801
A19: 40567 | B19: 19151.28 | C19: 98.55 | D19: =LN(B19/B18) -> 0.0075343377 | E19: =LN(C19/C18) -> -0.00050722801
A20: 40568 | B20: 18969.45 | C20: 98.4 | D20: =LN(B20/B19) -> -0.0095397637 | E20: =LN(C20/C19) -> -0.0015232295
A21: 40570 | B21: 18684.43 | C21: 98.85 | D21: =LN(B21/B20) -> -0.015139234 | E21: =LN(C21/C20) -> 0.0045627456
A22: 40571 | B22: 18395.97 | C22: 96.3 | D22: =LN(B22/B21) -> -0.015558938 | E22: =LN(C22/C21) -> -0.026135231
A23: 40574 | B23: 18327.76 | C23: 96.5 | D23: =LN(B23/B22) -> -0.0037147685 | E23: =LN(C23/C22) -> 0.0020746895
A24: 40575 | B24: 18022.22 | C24: 95.7 | D24: =LN(B24/B23) -> -0.016811409 | E24: =LN(C24/C23) -> -0.0083247099
A25: 40576 | B25: 18090.62 | C25: 95.5 | D25: =LN(B25/B24) -> 0.0037881309 | E25: =LN(C25/C24) -> -0.002092051
A26: 40577 | B26: 18449.31 | C26: 98.4 | D26: =LN(B26/B25) -> 0.0196334 | E26: =LN(C26/C25) -> 0.029914557
A27: 40578 | B27: 18008.15 | C27: 97.35 | D27: =LN(B27/B26) -> -0.024202538 | E27: =LN(C27/C26) -> -0.010728072
A28: 40581 | B28: 18037.19 | C28: 97.85 | D28: =LN(B28/B27) -> 0.0016113043 | E28: =LN(C28/C27) -> 0.005122962
A29: 40582 | B29: 17775.7 | C29: 95.7 | D29: =LN(B29/B28) -> -0.014603381 | E29: =LN(C29/C28) -> -0.022217395
... A3721: 46022 | B3721: 85220.6 | C3721: 264.55 | D3721: =LN(B3721/B3720) -> 0.0064218452 | E3721: =LN(C3721/C3720) -> 0.016195457

Sheet Income Statement
A1: INCOME STATEMENT
A3: Year | B3: 2019 | C3: 2020 | D3: 2021 | E3: 2022 | F3: 2023 | G3: 2024 | H3: 2025
A4: INCOME :
A5: Operating Income | B5: 34119.12 | C5: 36185.54 | D5: 37665.65 | E5: 39933.39 | F5: 43343.05 | G5: 42391.16 | H5: 41431.49
A6: Sales turnover / Operating Income | B6: 0 | C6: 0 | D6: 0 | E6: 0 | F6: 0 | G6: 0 | H6: 0
A7: Job Work & Service Income | B7: 33891.17 | C7: 35242.13 | D7: 37329.65 | E7: 39146.12 | F7: 41857.57 | G7: 41081.09 | H7: 40232.53
A8: Other Operating Divisions / Income | B8: 227.95 | C8: 943.41 | D8: 336 | E8: 787.27 | F8: 1485.48 | G8: 1310.07 | H8: 1198.96
A9: Discount Received | B9: 0 | C9: 0 | D9: 0 | E9: 0 | F9: 0 | G9: 0 | H9: 0
A10: Excise Duty | B10: 0 | C10: 0 | D10: 0 | E10: 0 | F10: 0 | G10: 0 | H10: 0
A11: Net Operating Income | B11: 34119.12 | C11: 36185.54 | D11: 37665.65 | E11: 39933.39 | F11: 43343.05 | G11: 42391.16 | H11: 41431.49
A12: Other Income | B12: 2282.94 | C12: 4227.68 | D12: 3366.82 | E12: 6391.37 | F12: 3867.59 | G12: 3549.01 | H12: 5208.54
A13: Dividend Income | B13: 149.78 | C13: 303.02 | D13: 662.78 | E13: 664.38 | F13: 671.71 | G13: 1038.17 | H13: 1377.87
A14: Interest Income | B14: 881.73 | C14: 1105.4 | D14: 1139.75 | E14: 1089.6 | F14: 1361.44 | G14: 1814.71 | H14: 2551.62
A15: Interest on Application Money | B15: 0 | C15: 0 | D15: 0 | E15: 0 | F15: 0 | G15: 0 | H15: 0
A16: Profit on sale of Fixed Assets | B16: 1.26 | C16: 1.14 | D16: 12.6 | E16: 0.02 | F16: 5.98 | G16: 0.36 | H16: 6.41
... A25: Total Income | B25: 36402.06 | C25: 40413.22 | D25: 41032.47 | E25: 46324.76 | F25: 47210.64 | G25: 45940.17 | H25: 46640.03
A26: EXPENDITURE :
A27: Electricity & Fuel Expenses | B27: 266.09 | C27: 286.76 | D27: 266.25 | E27: 295.18 | F27: 308.4 | G27: 317.57 | H27: 330.8
A28: Cost of Fuel / Coal Consumed | B28: 256.32 | C28: 282.75 | D28: 261.74 | E28: 290.84 | F28: 303.07 | G28: 312.09 | H28: 326.13
A29: Electricity Purchased | B29: 0 | C29: 0 | D29: 0 | E29: 0 | F29: 0 | G29: 0 | H29: 0
A30: Water Charges | B30: 9.77 | C30: 4.01 | D30: 4.51 | E30: 4.34 | F30: 5.33 | G30: 5.48 | H30: 4.67
A31: Operating Expenses | B31: 883.22 | C31: 872.83 | D31: 921.65 | E31: 1029.41 | F31: 1038.37 | G31: 951.54 | H31: 1039.55
A32: Stores Consumed | B32: 10.61 | C32: 7.02 | D32: 5.45 | E32: 5.22 | F32: 4.61 | G32: 3.79 | H32: 2.98
A33: Repairs | B33: 810.78 | C33: 761.8 | D33: 763.58 | E33: 818.19 | F33: 809.11 | G33: 812.95 | H33: 924.86
A34: Repairs - Plant & machinery | B34: 724.42 | C34: 669.59 | D34: 673.58 | E34: 719 | F34: 705.65 | G34: 690.26 | H34: 780.2
A35: Repairs - Building | B35: 86.36 | C35: 92.21 | D35: 90 | E35: 99.19 | F35: 103.46 | G35: 122.69 | H35: 144.66
A36: Other Operating Expenses | B36: 61.83 | C36: 104.01 | D36: 152.62 | E36: 206 | F36: 224.65 | G36: 134.8 | H36: 111.71
A37: Employee Cost | B37: 2300.54 | C37: 2448.29 | D37: 2594.37 | E37: 2627.92 | F37: 2763.9 | G37: 2635.49 | H37: 2847.24
A38: Salaries,Wages & Bonus | B38: 1838.79 | C38: 2019.71 | D38: 2068.18 | E38: 2087.2 | F38: 2147.44 | G38: 2089.1 | H38: 2219.64
... A92: Dividend Per Share Adj.(Rs) | B92: 4.69 | C92: 5.62 | D92: 6.75 | E92: 11.06 | F92: 11.06 | G92: 11.25 | H92: 9

Sheet Balance Sheet
A1: BALANCE SHEET
A3: Year | B3: 2019 | C3: 2020 | D3: 2021 | E3: 2022 | F3: 2023 | G3: 2024 | H3: 2025
A4: Shareholder's Funds
A5: Share Capital | B5: 5231.59 | C5: 5231.59 | D5: 5231.59 | E5: 6975.45 | F5: 6975.45 | G5: 9300.6 | H5: 9300.6
A6: Ordinary Capital | B6: 5231.59 | C6: 5231.59 | D6: 5231.59 | E6: 6975.45 | F6: 6975.45 | G6: 9300.6 | H6: 9300.6
A7: Reserves and Surplus | B7: 53785.55 | C7: 59208.1 | D7: 64347.25 | E7: 69176.12 | F7: 75868.73 | G7: 77566.45 | H7: 82915.05
A8: Total Shareholder's Fund | B8: 59017.14 | C8: 64439.69 | D8: 69578.84 | E8: 76151.57 | F8: 82844.18 | G8: 86867.05 | H8: 92215.65
A9: Non-Current Liabilities
A10: Long-Term Borrowings | B10: 131039.51 | C10: 135421.11 | D10: 129080.07 | E10: 114199.4 | F10: 113891.29 | G10: 105066.95 | H10: 109857.95
A11: Lease Liabilities | B11: - | C11: 0 | D11: 17.66 | E11: 27.04 | F11: 61.63 | G11: 37.24 | H11: 39.3
A12: Deferred Tax Liabilities (Net) | B12: 10093.02 | C12: 11381.85 | D12: 11941.88 | E12: 11424.78 | F12: 10619.9 | G12: 9981.4 | H12: 10038.68
A13: Deferred Tax Liability | B13: 17015.07 | C13: 20018.44 | D13: 22719 | E13: 25452.47 | F13: 26665.99 | G13: 27244.26 | H13: 27739.6
A14: Deferred Tax Assets | B14: 6922.05 | C14: 8636.59 | D14: 10777.12 | E14: 14027.69 | F14: 16046.09 | G14: 17262.86 | H14: 17700.92
A15: Other Long Term Liabilities | B15: 4384.01 | C15: 3876.67 | D15: 3914.45 | E15: 3763.89 | F15: 3761.77 | G15: 12088.36 | H15: 11489.1
A16: Long-Term Provisions | B16: 368.15 | C16: 424.71 | D16: 461.93 | E16: 517.05 | F16: 577.61 | G16: 643.11 | H16: 723.77
A17: Total Non Current Liabilities | B17: 145884.69 | C17: 151104.34 | D17: 145415.99 | E17: 129932.16 | F17: 128912.2 | G17: 127817.06 | H17: 132148.8
A18: Current Liabilities
A19: Short-Term Borrowings | B19: 4300 | C19: 3000 | D19: 13971.41 | E19: 20465.87 | F19: 14626.22 | G19: 18381.67 | H19: 21107.01
A20: Lease Liabilities | B20: - | C20: 0 | D20: 17.66 | E20: 27.04 | F20: 61.63 | G20: 37.24 | H20: 39.3
A21: Trade Payables | B21: 364.11 | C21: 225.72 | D21: 186.3 | E21: 266.14 | F21: 325.02 | G21: 354.07 | H21: 567.68
A22: Other Current Liabilities | B22: 36206.47 | C22: 36015.18 | D22: 23854.42 | E22: 20126.85 | F22: 20688.45 | G22: 11414.02 | H22: 11052
A23: Short-Term Provisions | B23: 700.59 | C23: 764.73 | D23: 1261.39 | E23: 932.31 | F23: 816.01 | G23: 583.36 | H23: 769.49
A24: Total Current Liabilities | B24: 41571.17 | C24: 40005.63 | D24: 39277.45 | E24: 41793.91 | F24: 36459.79 | G24: 30737.3 | H24: 33505.22
A25: Other Equity & Liabilities | B25: 0 | C25: 0 | D25: 0 | E25: 0 | F25: 0 | G25: 0 | H25: 0
A26: TOTAL EQUITY AND LIABILITIES | B26: 246473 | C26: 255549.66 | D26: 254272.28 | E26: 247877.64 | F26: 248216.17 | G26: 245421.41 | H26: 257869.67
A27: ASSETS
A28: Non-Current Assets
A29: Fixed Assets | B29: 197438.06 | C29: 200236.06 | D29: 194915.03 | E29: 187107.75 | F29: 179976.76 | G29: 172372.68 | H29: 166033.9
A30: Tangible Assets | B30: 162266.88 | C30: 168339.02 | D30: 175392.06 | E30: 178175.63 | F30: 170801.36 | G30: 161333.81 | H30: 152384.51
A31: Intangible Assets | B31: 1593.1 | C31: 1497.41 | D31: 1551.44 | E31: 1556.13 | F31: 1476.19 | G31: 1366.7 | H31: 1250.35
A32: Capital Work-in-Progress | B32: 33364.02 | C32: 30180.08 | D32: 17896.67 | E32: 7344.46 | F32: 7668.13 | G32: 9581.16 | H32: 12166.85
A33: Intangible assets under development | B33: 214.06 | C33: 219.55 | D33: 74.86 | E33: 31.53 | F33: 31.08 | G33: 91.01 | H33: 232.19
A34: Right-of-Use Assets | B34: - | C34: 0 | D34: 0 | E34: 0 | F34: 0 | G34: 0 | H34: 0
A35: Non-Current Investments | B35: 2756.56 | C35: 3763.69 | D35: 4265.39 | E35: 7228.53 | F35: 7414.95 | G35: 8733.47 | H35: 11314.17
A36: Deferred Tax Assets (net) | B36: 0 | C36: 0 | D36: 0 | E36: 0 | F36: 0 | G36: 0 | H36: 0
A37: Deferred Tax Assets | B37: 6922.05 | C37: 8636.59 | D37: 10777.12 | E37: 14027.69 | F37: 16046.09 | G37: 17262.86 | H37: 17700.92
A38: Deferred Tax Liability | B38: 17015.07 | C38: 20018.44 | D38: 22719 | E38: 25452.47 | F38: 26665.99 | G38: 27244.26 | H38: 27739.6
A39: Long-Term Loans and Advances | B39: 12184.06 | C39: 13391.07 | D39: 10829.36 | E39: 14704.44 | F39: 17927.76 | G39: 22399.8 | H39: 36846.86
A40: Other Non-Current Assets | B40: 8138.74 | C40: 9626.66 | D40: 8702.91 | E40: 8507.53 | F40: 9381.52 | G40: 8995.31 | H40: 8802.1
A41: Total Non Current Assets | B41: 220517.42 | C41: 227017.48 | D41: 218712.69 | E41: 217548.25 | F41: 214700.99 | G41: 212501.26 | H41: 222997.03
...

Sheet CashFlow Statement
A1: CASHFLOW STATEMENT
A3: Year | B3: 2019 | C3: 2020 | D3: 2021 | E3: 2022 | F3: 2023 | G3: 2024 | H3: 2025 | U3: 201703
A4: Cash Flow Summary
A5: Cash and Cash Equivalents at Beginning of the year | B5: 1516.21 | C5: 3645.7 | D5: 4805.14 | E5: 4430.05 | F5: 2457.47 | G5: 4146.24 | H5: 2620.55 | U5: 1540.64
A6: Net Cash from Operating Activities | B6: 23148.92 | C6: 29239.47 | D6: 27613.73 | E6: 24640.2 | F6: 35268.25 | G6: 34790.13 | H6: 31356.87 | U6: 21250.9
A7: Net Profit before Tax & Extraordinary Items | B7: 8268.03 | C7: 14687.14 | D7: 15109.36 | E7: 19694.17 | F7: 17525.41 | G7: 18006.22 | H7: 18678.83 | U7: 9569.76
A8: Depreciation | B8: 10200.67 | C8: 11073.18 | D8: 11711.68 | E8: 12550.58 | F8: 12939.88 | G8: 12601.43 | H8: 12352.23 | U8: 7662.8
A9: Interest (Net) | B9: 8244.87 | C9: 8725.27 | D9: 7374.94 | E9: 7134.98 | F9: 8478.77 | G9: 7323.41 | H9: 6972.6 | U9: 6037.29
A10: Dividend Received | B10: -149.78 | C10: -303.02 | D10: -662.78 | E10: -664.38 | F10: -671.71 | G10: -1038.17 | H10: -1377.87 | U10: -62.73
A11: P/L on Sales of Assets | B11: 25.58 | C11: 17.2 | D11: 2.49 | E11: 28.39 | F11: 22.09 | G11: 19.99 | H11: 1.64 | U11: 3.8
A12: P/L on Sales of Invest | B12: 0 | C12: 0 | D12: 0 | E12: -3775.46 | F12: 0 | G12: -9.46 | H12: -264.11 | U12: -50.57
A13: Prov. & W/O (Net) | B13: 380.45 | C13: -141.22 | D13: -17.06 | E13: -8.92 | F13: 35.25 | G13: 105.11 | H13: -23.8 | U13: 5.04
A14: P/L in Forex | B14: -941.22 | C14: -1573.05 | D14: 1022.07 | E14: -42.72 | F14: -159.19 | G14: 457.82 | H14: 359.58 | U14: 825.52
A15: Fin. Lease & Rental Chrgs | B15: 0 | C15: 0 | D15: -81.18 | E15: -73.12 | F15: -150.8 | G15: -72.25 | H15: -93.79 | U15: 0
A16: Others | B16: 4019.07 | C16: -1152.13 | D16: -2484.22 | E16: -9.24 | F16: 147.05 | G16: -175.87 | H16: -1048.81 | U16: -985.38
... A83: Cash and Cash Equivalents at End of the year | B83: 3643.14 | C83: 4805.14 | D83: 4430.05 | E83: 2457.47 | F83: 4146.24 | G83: 2620.55 | H83: 3723.53 | U83: 3228.43

Sheet Assumptions
A1: ASSUMPTION
I2: Scenarios: | J2: Revenue Growth | K2: Rate
A3: Selected Case | B3: Case 3 | C3: =IF(B3="Case 1","Optimistic",IF(B3="Case 2","Base case","Worst case")) -> Worst case | I3: Case 1 | J3: Optimistic | K3: 11.00% | R3: Case 1 | S3: 0.11 | T3: 0.07 | U3: 0.07 | V3: 0.96 | W3: 0.975 | X3: 0.05 | Y3: 0.25 | Z3: 0.48 | AA3: 0.1 | AB3: 0.94 | AC3: 1.05 | AD3: 0.1 | AE3: 0.12 | AF3: 0.08 | AG3: 0.93
I4: Case 2 | J4: Base case | K4: 8.00% | R4: Case 2 | S4: 0.08 | T4: 0.05 | U4: 0.06 | V4: 0.97 | W4: 0.985 | X4: 0.04 | Y4: 0.25 | Z4: 0.46 | AA4: 0.08 | AB4: 0.95 | AC4: 1.03 | AD4: 0.08 | AE4: 0.1 | AF4: 0.07 | AG4: 0.95
I5: Case 3 | J5: Worst case | K5: 5.00% | R5: Case 3 | S5: 0.05 | T5: 0.03 | U5: 0.04 | V5: 0.98 | W5: 0.995 | X5: 0.03 | Y5: 0.25 | Z5: 0.42 | AA5: 0.05 | AB5: 0.97 | AC5: 1.01 | AD5: 0.05 | AE5: 0.07 | AF5: 0.05 | AG5: 0.97
A6: P&L Assumptions | B6: INR in Cr.
A8: Particulars | B8: 2019 | C8: 2020 | D8: 2021 | E8: 2022 | F8: 2023 | G8: 2024 | H8: 2025 | I8: 2026 | J8: 2027 | K8: 2028 | L8: 2029 | M8: 2030
B9: Actual | C9: Actual | D9: Actual | E9: Actual | F9: Actual | G9: Actual | H9: Actual | I9: Forecast | J9: Forecast | K9: Forecast | L9: Forecast | M9: Forecast
A10: Transmission Income / Operating Income | B10: 34119.12 | C10: 36185.54 | D10: 37665.65 | E10: 39933.39 | F10: 43343.05 | G10: 42391.16 | H10: 41431.49 | I10: =H10*(1+INDEX(S$3:S$5,MATCH($B$3,R$3:R$5,0))) -> 43503.065 | J10: =I10*(1+INDEX(S$3:S$5,MATCH($B$3,R$3:R$5,0))) -> 45678.218 | K10: =J10*(1+INDEX(S$3:S$5,MATCH($B$3,R$3:R$5,0))) -> 47962.129 | L10: =K10*(1+INDEX(S$3:S$5,MATCH($B$3,R$3:R$5,0))) -> 50360.235 | M10: =L10*(1+INDEX(S$3:S$5,MATCH($B$3,R$3:R$5,0))) -> 52878.247
A11: y-o-y growth % | B11: 0.14629901 | C11: 0.060564868 | D11: 0.040903355 | E11: 0.060207112 | F11: 0.085383685 | G11: -0.021961768 | H11: -0.022638446 | I11: =(I10-H10)/H10 -> 0.05 | J11: =(J10-I10)/I10 -> 0.05 | K11: =(K10-J10)/J10 -> 0.05 | L11: =(L10-K10)/K10 -> 0.05 | M11: =(M10-L10)/L10 -> 0.05
A13: Other Income (Dividend, Interest, Lease etc.) | B13: 2282.94 | C13: 4227.68 | D13: 3366.82 | E13: 6391.37 | F13: 3867.59 | G13: 3549.01 | H13: 5208.54 | I13: =H13*(1+INDEX(T$3:T$5,MATCH($B$3,R$3:R$5,0))) -> 5364.7962 | J13: =I13*(1+INDEX(T$3:T$5,MATCH($B$3,R$3:R$5,0))) -> 5525.7401 | K13: =J13*(1+INDEX(T$3:T$5,MATCH($B$3,R$3:R$5,0))) -> 5691.5123 | L13: =K13*(1+INDEX(T$3:T$5,MATCH($B$3,R$3:R$5,0))) -> 5862.2577 | M13: =L13*(1+INDEX(T$3:T$5,MATCH($B$3,R$3:R$5,0))) -> 6038.1254
A14: % of Operating Income | B14: 0.06691087 | C14: 0.11683341 | D14: 0.089387014 | E14: 0.16005077 | F14: 0.089232068 | G14: 0.083720521 | H14: 0.12571452 | I14: =I13/I10 -> 0.12331996 | J14: =J13/J10 -> 0.12097101 | K14: =K13/K10 -> 0.1186668 | L14: =L13/L10 -> 0.11640648 | M14: =M13/M10 -> 0.11418921
A16: Employee Cost | B16: 2300.54 | C16: 2448.29 | D16: 2594.37 | E16: 2627.92 | F16: 2763.9 | G16: 2635.49 | H16: 2847.24 | I16: =H16*(1+INDEX(U$3:U$5,MATCH($B$3,R$3:R$5,0))) -> 2961.1296 | J16: =I16*(1+INDEX(U$3:U$5,MATCH($B$3,R$3:R$5,0))) -> 3079.5748 | K16: =J16*(1+INDEX(U$3:U$5,MATCH($B$3,R$3:R$5,0))) -> 3202.7578 | L16: =K16*(1+INDEX(U$3:U$5,MATCH($B$3,R$3:R$5,0))) -> 3330.8681 | M16: =L16*(1+INDEX(U$3:U$5,MATCH($B$3,R$3:R$5,0))) -> 3464.1028
A17: % of Operating Income | B17: 0.06742671 | C17: 0.067659347 | D17: 0.068878939 | E17: 0.065807586 | F17: 0.063768009 | G17: 0.062170745 | H17: 0.068721641 | I17: =I16/I10 -> 0.06806715 | J17: =J16/J10 -> 0.067418891 | K17: =K16/K10 -> 0.066776806 | L17: =L16/L10 -> 0.066140837 | M17: =M16/M10 -> 0.065510924
A19: Finance Cost (Interest & Financial Charges) | B19: 9091.42 | C19: 9813.62 | D19: 8501.01 | E19: 8210.94 | F19: 9744.25 | G19: 9046.87 | H19: 9479.32 | I19: =H19*INDEX(V$3:V$5,MATCH($B$3,R$3:R$5,0)) -> 9289.7336 | J19: =I19*INDEX(V$3:V$5,MATCH($B$3,R$3:R$5,0)) -> 9103.9389 | K19: =J19*INDEX(V$3:V$5,MATCH($B$3,R$3:R$5,0)) -> 8921.8601 | L19: =K19*INDEX(V$3:V$5,MATCH($B$3,R$3:R$5,0)) -> 8743.4229 | M19: =L19*INDEX(V$3:V$5,MATCH($B$3,R$3:R$5,0)) -> 8568.5545
A20: % of Operating Income | B20: 0.26646115 | C20: 0.27120281 | D20: 0.22569662 | E20: 0.2056159 | F20: 0.2248169 | G20: 0.21341407 | H20: 0.22879505 | I20: =I19/I10 -> 0.21354205 | J20: =J19/J10 -> 0.19930591 | K20: =K19/K10 -> 0.18601885 | L20: =L19/L10 -> 0.1736176 | M20: =M19/M10 -> 0.16204309
A22: Depreciation & Amortisation | B22: 10200.67 | C22: 11073.18 | D22: 11711.68 | E22: 12550.58 | F22: 12939.88 | G22: 12558.19 | H22: 12352.23 | I22: =H22*INDEX(W$3:W$5,MATCH($B$3,R$3:R$5,0)) -> 12290.469 | J22: =I22*INDEX(W$3:W$5,MATCH($B$3,R$3:R$5,0)) -> 12229.017 | K22: =J22*INDEX(W$3:W$5,MATCH($B$3,R$3:R$5,0)) -> 12167.871 | L22: =K22*INDEX(W$3:W$5,MATCH($B$3,R$3:R$5,0)) -> 12107.032 | M22: =L22*INDEX(W$3:W$5,MATCH($B$3,R$3:R$5,0)) -> 12046.497
A23: % of Operating Income | B23: 0.29897225 | C23: 0.30601119 | D23: 0.31093795 | E23: 0.31428787 | F23: 0.29854567 | G23: 0.29624549 | H23: 0.29813627 | I23: =I22/I10 -> 0.28251961 | J23: =J22/J10 -> 0.26772096 | K23: =K22/K10 -> 0.25369749 | L23: =L22/L10 -> 0.24040857 | M23: =M22/M10 -> 0.22781574
A25: Other Operating Expenses (Repairs, Admin etc.) | B25: 5847.32 | C25: 2747.38 | D25: 3200.49 | E25: 3130.5 | F25: 4291.49 | G25: 3593.03 | H25: 3341.81 | I25: =H25*(1+INDEX(X$3:X$5,MATCH($B$3,R$3:R$5,0))) -> 3442.0643 | J25: =I25*(1+INDEX(X$3:X$5,MATCH($B$3,R$3:R$5,0))) -> 3545.3262 | K25: =J25*(1+INDEX(X$3:X$5,MATCH($B$3,R$3:R$5,0))) -> 3651.686 | L25: =K25*(1+INDEX(X$3:X$5,MATCH($B$3,R$3:R$5,0))) -> 3761.2366 | M25: =L25*(1+INDEX(X$3:X$5,MATCH($B$3,R$3:R$5,0))) -> 3874.0737
A26: % of Operating Income | B26: 0.17137957 | C26: 0.075924803 | D26: 0.084971055 | E26: 0.078393044 | F26: 0.099012183 | G26: 0.084758945 | H26: 0.080658697 | I26: =I25/I10 -> 0.079122341 | J26: =J25/J10 -> 0.077615249 | K26: =K25/K10 -> 0.076136863 | L26: =L25/L10 -> 0.074686637 | M26: =M25/M10 -> 0.073264034
A28: EBITDA | B28: 28254.2 | C28: 35217.55 | D28: 35237.61 | E28: 40566.34 | F28: 40155.25 | G28: 39711.65 | H28: 40450.98 | I28: =I10+I13-I16-I25 -> 42464.667 | J28: =J10+J13-J16-J25 -> 44579.057 | K28: =K10+K13-K16-K25 -> 46799.197 | L28: =L10+L13-L16-L25 -> 49130.388 | M28: =M10+M13-M16-M25 -> 51578.196
A29: EBITDA Margin % | B29: 0.82810459 | C29: 0.97324926 | D29: 0.93553702 | E29: 1.0158501 | F29: 0.92645188 | G29: 0.93679083 | H29: 0.97633418 | I29: =I28/I10 -> 0.97613047 | J29: =J28/J10 -> 0.97593687 | K29: =K28/K10 -> 0.97575313 | L29: =L28/L10 -> 0.97557901 | M29: =M28/M10 -> 0.97541425
A31: Profit Before Tax (PBT) | B31: 8962.11 | C31: 14330.75 | D31: 15024.92 | E31: 19804.82 | F31: 17471.12 | G31: 18106.59 | H31: 18619.43 | I31: =I28-I19-I22 -> 20884.464 | J31: =J28-J19-J22 -> 23246.101 | K31: =K28-K19-K22 -> 25709.466 | L31: =L28-L19-L22 -> 28279.933 | M31: =M28-M19-M22 -> 30963.144
A32: PBT Margin % | B32: 0.26267119 | C32: 0.39603527 | D32: 0.39890245 | E32: 0.49594637 | F32: 0.40308931 | G32: 0.42713127 | H32: 0.44940286 | I32: =I31/I10 -> 0.48006881 | J32: =J31/J10 -> 0.50890999 | K32: =K31/K10 -> 0.53603679 | L32: =L31/L10 -> 0.56155284 | M32: =M31/M10 -> 0.58555543
A34: Income Tax | B34: 2489.43 | C34: 2230.74 | D34: 2529.11 | E34: 3282.06 | F34: 2913.67 | G34: 3236.43 | H34: 3177.83 | I34: =I31*INDEX(Y$3:Y$5,MATCH($B$3,R$3:R$5,0)) -> 5221.1161 | J34: =J31*INDEX(Y$3:Y$5,MATCH($B$3,R$3:R$5,0)) -> 5811.5253 | K34: =K31*INDEX(Y$3:Y$5,MATCH($B$3,R$3:R$5,0)) -> 6427.3664 | L34: =L31*INDEX(Y$3:Y$5,MATCH($B$3,R$3:R$5,0)) -> 7069.9833 | M34: =M31*INDEX(Y$3:Y$5,MATCH($B$3,R$3:R$5,0)) -> 7740.7861
A35: Effective Tax Rate (% of PBT) | B35: 0.27777276 | C35: 0.15566108 | D35: 0.16832768 | E35: 0.16572026 | F35: 0.16677065 | G35: 0.17874321 | H35: 0.17067279 | I35: =I34/I31 -> 0.25 | J35: =J34/J31 -> 0.25 | K35: =K34/K31 -> 0.25 | L35: =L34/L31 -> 0.25 | M35: =M34/M31 -> 0.25
A37: Reported Net Profit (PAT) | B37: 9938.55 | C37: 10811.18 | D37: 11935.78 | E37: 17093.76 | F37: 15333.02 | G37: 15474.61 | H37: 15353.57 | I37: =I31-I34 -> 15663.348 | J37: =J31-J34 -> 17434.576 | K37: =K31-K34 -> 19282.099 | L37: =L31-L34 -> 21209.95 | M37: =M31-M34 -> 23222.358
A38: PAT Margin % | B38: 0.29128975 | C38: 0.29877072 | D38: 0.31688767 | E38: 0.42805682 | F38: 0.3537596 | G38: 0.36504333 | H38: 0.37057731 | I38: =I37/I10 -> 0.36005161 | J38: =J37/J10 -> 0.38168249 | K38: =K37/K10 -> 0.40202759 | L38: =L37/L10 -> 0.42116463 | M38: =M37/M10 -> 0.43916657
A40: Dividend Paid | B40: 3050.02 | C40: 3118.02 | D40: 4708.43 | E40: 8719.32 | F40: 6975.45 | G40: 7905.51 | H40: 7207.97 | I40: =I37*INDEX(Z$3:Z$5,MATCH($B$3,R$3:R$5,0)) -> 6578.6063 | J40: =J37*INDEX(Z$3:Z$5,MATCH($B$3,R$3:R$5,0)) -> 7322.5219 | K40: =K37*INDEX(Z$3:Z$5,MATCH($B$3,R$3:R$5,0)) -> 8098.4816 | L40: =L37*INDEX(Z$3:Z$5,MATCH($B$3,R$3:R$5,0)) -> 8908.1789 | M40: =M37*INDEX(Z$3:Z$5,MATCH($B$3,R$3:R$5,0)) -> 9753.3904
A41: Dividend Payout Ratio | B41: 0.30688783 | C41: 0.288407 | D41: 0.39448029 | E41: 0.51008789 | F41: 0.45492995 | G41: 0.51086974 | H41: 0.46946541 | I41: =I40/I37 -> 0.42 | J41: =J40/J37 -> 0.42 | K41: =K40/K37 -> 0.42 | L41: =L40/L37 -> 0.42 | M41: =M40/M37 -> 0.42
A44: Balance Sheet & Capital Expenditure Assumptions
C45: INR in Cr.
A46: Particulars | B46: 2019 | C46: 2020 | D46: 2021 | E46: 2022 | F46: 2023 | G46: 2024 | H46: 2025 | I46: 2026 | J46: 2027 | K46: 2028 | L46: 2029 | M46: 2030
B47: Actual | C47: Actual | D47: Actual | E47: Actual | F47: Actual | G47: Actual | H47: Actual | I47: Forecast | J47: Forecast | K47: Forecast | L47: Forecast | M47: Forecast
A48: Net Fixed Assets (Net Block) | B48: 197438.06 | C48: 200236.06 | D48: 194915.03 | E48: 187107.75 | F48: 179976.76 | G48: 172372.68 | H48: 166033.9 | I48: =H48*INDEX(W$3:W$5,MATCH($B$3,R$3:R$5,0)) -> 165203.73 | J48: =I48*INDEX(W$3:W$5,MATCH($B$3,R$3:R$5,0)) -> 164377.71 | K48: =J48*INDEX(W$3:W$5,MATCH($B$3,R$3:R$5,0)) -> 163555.82 | L48: =K48*INDEX(W$3:W$5,MATCH($B$3,R$3:R$5,0)) -> 162738.04 | M48: =L48*INDEX(W$3:W$5,MATCH($B$3,R$3:R$5,0)) -> 161924.35
A49: YoY Change % | C49: 0.014171533 | D49: -0.026573785 | E49: -0.040054787 | F49: -0.038111676 | G49: -0.042250344 | H49: -0.036773693 | I49: =I48/H48-1 -> -0.005 | J49: =J48/I48-1 -> -0.005 | K49: =K48/J48-1 -> -0.005 | L49: =L48/K48-1 -> -0.005 | M49: =M48/L48-1 -> -0.005
A51: Capital Expenditure (Capex) | B51: 19462.03 | C51: 8006.12 | D51: 6389.23 | E51: 3645.32 | F51: 3064.54 | G51: 5517.74 | H51: 5142.74 | I51: =H51*(1+INDEX(AA$3:AA$5,MATCH($B$3,R$3:R$5,0))) -> 5399.877 | J51: =I51*(1+INDEX(AA$3:AA$5,MATCH($B$3,R$3:R$5,0))) -> 5669.8709 | K51: =J51*(1+INDEX(AA$3:AA$5,MATCH($B$3,R$3:R$5,0))) -> 5953.3644 | L51: =K51*(1+INDEX(AA$3:AA$5,MATCH($B$3,R$3:R$5,0))) -> 6251.0326 | M51: =L51*(1+INDEX(AA$3:AA$5,MATCH($B$3,R$3:R$5,0))) -> 6563.5842
A52: Capex as % of Net Fixed Assets | B52: 0.098572838 | C52: 0.039983408 | D52: 0.032779566 | E52: 0.019482464 | F52: 0.017027421 | G52: 0.032010525 | H52: 0.030974036 | I52: =I51/I48 -> 0.032686169 | J52: =J51/J48 -> 0.034492942 | K52: =K51/K48 -> 0.036399587 | L52: =L51/L48 -> 0.038411624 | M52: =M51/M48 -> 0.04053488
A54: Trade Receivables | B54: 4649.8 | C54: 4867.9 | D54: 8470.2 | E54: 9106.82 | F54: 14304.13 | G54: 10825.8 | H54: 7273.25 | I54: =H54*INDEX(AG$3:AG$5,MATCH($B$3,R$3:R$5,0)) -> 7055.0525 | J54: =I54*INDEX(AG$3:AG$5,MATCH($B$3,R$3:R$5,0)) -> 6843.4009 | K54: =J54*INDEX(AG$3:AG$5,MATCH($B$3,R$3:R$5,0)) -> 6638.0989 | L54: =K54*INDEX(AG$3:AG$5,MATCH($B$3,R$3:R$5,0)) -> 6438.9559 | M54: =L54*INDEX(AG$3:AG$5,MATCH($B$3,R$3:R$5,0)) -> 6245.7873
A55: Days Receivables | B55: 49.742696 | C55: 49.102031 | D55: 82.080702 | E55: 83.238345 | F55: 120.45778 | G55: 93.213231 | H55: 64.075327 | I55: =H55 -> 64.075327 | J55: =I55 -> 64.075327 | K55: =J55 -> 64.075327 | L55: =K55 -> 64.075327 | M55: =L55 -> 64.075327
...

Sheet Financial Statement
A1: FINANCIAL STATEMENTS
A2: Number of Days | B2: 365 | C2: 365 | D2: 365 | E2: 365 | F2: 365 | G2: 365 | H2: 365 | I2: 365 | J2: 365 | K2: 365 | L2: 365 | M2: 365
A3: Selected Case ▼ | B3: Case 3 | C3: =IF(B3="Case 1","Optimistic",IF(B3="Case 2","Base Case","Worst Case")) -> Worst Case | S3: Case 1 | T3: 0.11 | U3: 0.07 | V3: 0.96 | W3: 0.975 | X3: 0.05 | Y3: 0.25 | Z3: 0.48 | AA3: 0.1 | AB3: 0.07
B4: ACTUAL PERIOD | I4: FORECASTED PERIOD | S4: Case 2 | T4: 0.08 | U4: 0.06 | V4: 0.97 | W4: 0.985 | X4: 0.04 | Y4: 0.25 | Z4: 0.46 | AA4: 0.08 | AB4: 0.05
S5: Case 3 | T5: 0.05 | U5: 0.04 | V5: 0.98 | W5: 0.995 | X5: 0.03 | Y5: 0.25 | Z5: 0.42 | AA5: 0.05 | AB5: 0.03
A6: Profit and Loss Statement
A8: Particulars | B8: 2019 Actual | C8: 2020 Actual | D8: 2021 Actual | E8: 2022 Actual | F8: 2023 Actual | G8: 2024 Actual | H8: 2025 Actual | I8: 2026 Forecast | J8: 2027 Forecast | K8: 2028 Forecast | L8: 2029 Forecast | M8: 2030 Forecast | N8: Trend
A9: Transmission Income (Operating Revenue) | B9: 34119.12 | C9: 36185.54 | D9: 37665.65 | E9: 39933.39 | F9: 43343.05 | G9: 42391.16 | H9: 41431.49 | I9: =H9*(1+INDEX(T$3:T$5,MATCH($B$3,S$3:S$5,0))) -> 43503.065 | J9: =I9*(1+INDEX(T$3:T$5,MATCH($B$3,S$3:S$5,0))) -> 45678.218 | K9: =J9*(1+INDEX(T$3:T$5,MATCH($B$3,S$3:S$5,0))) -> 47962.129 | L9: =K9*(1+INDEX(T$3:T$5,MATCH($B$3,S$3:S$5,0))) -> 50360.235 | M9: =L9*(1+INDEX(T$3:T$5,MATCH($B$3,S$3:S$5,0))) -> 52878.247 | N9: Growth Driver
A10: Other Income (Interest, Dividend, Lease etc.) | B10: 2282.94 | C10: 4227.68 | D10: 3366.82 | E10: 6391.37 | F10: 3867.59 | G10: 3549.01 | H10: 5208.54 | I10: =H10*(1+INDEX(AB$3:AB$5,MATCH($B$3,S$3:S$5,0))) -> 5364.7962 | J10: =I10*(1+INDEX(AB$3:AB$5,MATCH($B$3,S$3:S$5,0))) -> 5525.7401 | K10: =J10*(1+INDEX(AB$3:AB$5,MATCH($B$3,S$3:S$5,0))) -> 5691.5123 | L10: =K10*(1+INDEX(AB$3:AB$5,MATCH($B$3,S$3:S$5,0))) -> 5862.2577 | M10: =L10*(1+INDEX(AB$3:AB$5,MATCH($B$3,S$3:S$5,0))) -> 6038.1254
A11: Total Revenue | B11: 36402.06 | C11: 40413.22 | D11: 41032.47 | E11: 46324.76 | F11: 47210.64 | G11: 45940.17 | H11: 46640.03 | I11: =I9+I10 -> 48867.861 | J11: =J9+J10 -> 51203.958 | K11: =K9+K10 -> 53653.641 | L11: =L9+L10 -> 56222.493 | M11: =M9+M10 -> 58916.372
A13: Employee Benefit Expenses | B13: 2300.54 | C13: 2448.29 | D13: 2594.37 | E13: 2627.92 | F13: 2763.9 | G13: 2635.49 | H13: 2847.24 | I13: =H13*(1+INDEX(U$3:U$5,MATCH($B$3,S$3:S$5,0))) -> 2961.1296 | J13: =I13*(1+INDEX(U$3:U$5,MATCH($B$3,S$3:S$5,0))) -> 3079.5748 | K13: =J13*(1+INDEX(U$3:U$5,MATCH($B$3,S$3:S$5,0))) -> 3202.7578 | L13: =K13*(1+INDEX(U$3:U$5,MATCH($B$3,S$3:S$5,0))) -> 3330.8681 | M13: =L13*(1+INDEX(U$3:U$5,MATCH($B$3,S$3:S$5,0))) -> 3464.1028
A14: Other Operating Expenses (Repairs, Admin & Misc) | B14: 5847.32 | C14: 2747.38 | D14: 3200.49 | E14: 3130.5 | F14: 4291.49 | G14: 3593.03 | H14: 3341.81 | I14: =H14*(1+INDEX(X$3:X$5,MATCH($B$3,S$3:S$5,0))) -> 3442.0643 | J14: =I14*(1+INDEX(X$3:X$5,MATCH($B$3,S$3:S$5,0))) -> 3545.3262 | K14: =J14*(1+INDEX(X$3:X$5,MATCH($B$3,S$3:S$5,0))) -> 3651.686 | L14: =K14*(1+INDEX(X$3:X$5,MATCH($B$3,S$3:S$5,0))) -> 3761.2366 | M14: =L14*(1+INDEX(X$3:X$5,MATCH($B$3,S$3:S$5,0))) -> 3874.0737
A15: EBITDA | B15: 28254.2 | C15: 35217.55 | D15: 35237.61 | E15: 40566.34 | F15: 40155.25 | G15: 39711.65 | H15: 40450.98 | I15: =I11-I13-I14 -> 42464.667 | J15: =J11-J13-J14 -> 44579.057 | K15: =K11-K13-K14 -> 46799.197 | L15: =L11-L13-L14 -> 49130.388 | M15: =M11-M13-M14 -> 51578.196
A17: Depreciation And Amortisation Expenses | B17: 10200.67 | C17: 11073.18 | D17: 11711.68 | E17: 12550.58 | F17: 12939.88 | G17: 12558.19 | H17: 12352.23 | I17: =H17*INDEX(W$3:W$5,MATCH($B$3,S$3:S$5,0)) -> 12290.469 | J17: =I17*INDEX(W$3:W$5,MATCH($B$3,S$3:S$5,0)) -> 12229.017 | K17: =J17*INDEX(W$3:W$5,MATCH($B$3,S$3:S$5,0)) -> 12167.871 | L17: =K17*INDEX(W$3:W$5,MATCH($B$3,S$3:S$5,0)) -> 12107.032 | M17: =L17*INDEX(W$3:W$5,MATCH($B$3,S$3:S$5,0)) -> 12046.497
A18: EBIT | B18: 18053.53 | C18: 24144.37 | D18: 23525.93 | E18: 28015.76 | F18: 27215.37 | G18: 27153.46 | H18: 28098.75 | I18: =I15-I17 -> 30174.198 | J18: =J15-J17 -> 32350.04 | K18: =K15-K17 -> 34631.326 | L18: =L15-L17 -> 37023.356 | M18: =M15-M17 -> 39531.699
A20: Finance Cost (Interest & Financial Charges) | B20: 9091.42 | C20: 9813.62 | D20: 8501.01 | E20: 8210.94 | F20: 9744.25 | G20: 9046.87 | H20: 9479.32 | I20: =H20*INDEX(V$3:V$5,MATCH($B$3,S$3:S$5,0)) -> 9289.7336 | J20: =I20*INDEX(V$3:V$5,MATCH($B$3,S$3:S$5,0)) -> 9103.9389 | K20: =J20*INDEX(V$3:V$5,MATCH($B$3,S$3:S$5,0)) -> 8921.8601 | L20: =K20*INDEX(V$3:V$5,MATCH($B$3,S$3:S$5,0)) -> 8743.4229 | M20: =L20*INDEX(V$3:V$5,MATCH($B$3,S$3:S$5,0)) -> 8568.5545
A21: EBT (Profit Before Tax) | B21: 8962.11 | C21: 14330.75 | D21: 15024.92 | E21: 19804.82 | F21: 17471.12 | G21: 18106.59 | H21: 18619.43 | I21: =I18-I20 -> 20884.464 | J21: =J18-J20 -> 23246.101 | K21: =K18-K20 -> 25709.466 | L21: =L18-L20 -> 28279.933 | M21: =M18-M20 -> 30963.144
A22: Tax Rate | B22: 0.27777276 | C22: 0.15566108 | D22: 0.16832768 | E22: 0.16572026 | F22: 0.16677065 | G22: 0.17874321 | H22: 0.17067279 | I22: =INDEX(Y$3:Y$5,MATCH($B$3,S$3:S$5,0)) -> 0.25 | J22: =INDEX(Y$3:Y$5,MATCH($B$3,S$3:S$5,0)) -> 0.25 | K22: =INDEX(Y$3:Y$5,MATCH($B$3,S$3:S$5,0)) -> 0.25 | L22: =INDEX(Y$3:Y$5,MATCH($B$3,S$3:S$5,0)) -> 0.25 | M22: =INDEX(Y$3:Y$5,MATCH($B$3,S$3:S$5,0)) -> 0.25
A23: Current Tax | B23: 2489.43 | C23: 2230.74 | D23: 2529.11 | E23: 3282.06 | F23: 2913.67 | G23: 3236.43 | H23: 3177.83 | I23: =I21*INDEX(Y$3:Y$5,MATCH($B$3,S$3:S$5,0)) -> 5221.1161 | J23: =J21*INDEX(Y$3:Y$5,MATCH($B$3,S$3:S$5,0)) -> 5811.5253 | K23: =K21*INDEX(Y$3:Y$5,MATCH($B$3,S$3:S$5,0)) -> 6427.3664 | L23: =L21*INDEX(Y$3:Y$5,MATCH($B$3,S$3:S$5,0)) -> 7069.9833 | M23: =M21*INDEX(Y$3:Y$5,MATCH($B$3,S$3:S$5,0)) -> 7740.7861
A24: Deferred Tax | B24: -3465.87 | C24: 1288.83 | D24: 560.03 | E24: -571 | F24: -775.57 | G24: -604.45 | H24: 88.03 | I24: 0 | J24: 0 | K24: 0 | L24: 0 | M24: 0
A25: Net Income (PAT) | B25: 9938.55 | C25: 10811.18 | D25: 11935.78 | E25: 17093.76 | F25: 15333.02 | G25: 15474.61 | H25: 15353.57 | I25: =I21-I23 -> 15663.348 | J25: =J21-J23 -> 17434.576 | K25: =K21-K23 -> 19282.099 | L25: =L21-L23 -> 21209.95 | M25: =M21-M23 -> 23222.358
A27: EPS (Rs.) | B27: 19 | C27: 20.67 | D27: 22.81 | E27: 24.51 | F27: 21.98 | G27: 16.64 | H27: 16.51 | I27: =I25/930.06 -> 16.841223 | J27: =J25/930.06 -> 18.745647 | K27: =K25/930.06 -> 20.732102 | L27: =L25/930.06 -> 22.804926 | M27: =M25/930.06 -> 24.968667
A28: Dividend Paid | B28: 3050.02 | C28: 3118.02 | D28: 4708.43 | E28: 8719.32 | F28: 6975.45 | G28: 7905.51 | H28: 7207.97 | I28: =I25*INDEX(Z$3:Z$5,MATCH($B$3,S$3:S$5,0)) -> 6578.6063 | J28: =J25*INDEX(Z$3:Z$5,MATCH($B$3,S$3:S$5,0)) -> 7322.5219 | K28: =K25*INDEX(Z$3:Z$5,MATCH($B$3,S$3:S$5,0)) -> 8098.4816 | L28: =L25*INDEX(Z$3:Z$5,MATCH($B$3,S$3:S$5,0)) -> 8908.1789 | M28: =M25*INDEX(Z$3:Z$5,MATCH($B$3,S$3:S$5,0)) -> 9753.3904
A29: Dividend Payout Ratio | B29: 0.30688783 | C29: 0.288407 | D29: 0.39448029 | E29: 0.51008789 | F29: 0.45492995 | G29: 0.51086974 | H29: 0.46946541 | I29: =I28/I25 -> 0.42 | J29: =J28/J25 -> 0.42 | K29: =K28/K25 -> 0.42 | L29: =L28/L25 -> 0.42 | M29: =M28/M25 -> 0.42
A31: Balance Sheet | B31: INR in Cr.
B33: ACTUAL PERIOD | I33: FORECASTED PERIOD
A34: INR in Cr. | B34: 2019 Actual | C34: 2020 Actual | D34: 2021 Actual | E34: 2022 Actual | F34: 2023 Actual | G34: 2024 Actual | H34: 2025 Actual | I34: 2026 Forecast | J34: 2027 Forecast | K34: 2028 Forecast | L34: 2029 Forecast | M34: 2030 Forecast | N34: Trend
A35: Share Capital | B35: 5231.59 | C35: 5231.59 | D35: 5231.59 | E35: 6975.45 | F35: 6975.45 | G35: 9300.6 | H35: 9300.6 | I35: =H35 -> 9300.6 | J35: =I35 -> 9300.6 | K35: =J35 -> 9300.6 | L35: =K35 -> 9300.6 | M35: =L35 -> 9300.6
A36: Reserves & Surplus | B36: 53785.55 | C36: 59208.1 | D36: 64347.25 | E36: 69176.12 | F36: 75868.73 | G36: 77566.45 | H36: 82915.05 | I36: =H36+I25-I28 -> 91999.792 | J36: =I36+J25-J28 -> 102111.85 | K36: =J36+K25-K28 -> 113295.46 | L36: =K36+L25-L28 -> 125597.23 | M36: =L36+M25-M28 -> 139066.2
A37: Total Equity | B37: 59017.14 | C37: 64439.69 | D37: 69578.84 | E37: 76151.57 | F37: 82844.18 | G37: 86867.05 | H37: 92215.65 | I37: =I35+I36 -> 101300.39 | J37: =J35+J36 -> 111412.45 | K37: =K35+K36 -> 122596.06 | L37: =L35+L36 -> 134897.83 | M37: =M35+M36 -> 148366.8
A39: Long Term Borrowings | B39: 131039.51 | C39: 135421.11 | D39: 129080.07 | E39: 114199.4 | F39: 113891.29 | G39: 105066.95 | H39: 109857.95 | I39: =H39*0.95 -> 104365.05 | J39: =I39*0.95 -> 99146.8 | K39: =J39*0.95 -> 94189.46 | L39: =K39*0.95 -> 89479.987 | M39: =L39*0.95 -> 85005.988
A40: Deferred Tax Liabilities [Net] | B40: 10093.02 | C40: 11381.85 | D40: 11941.88 | E40: 11424.78 | F40: 10619.9 | G40: 9981.4 | H40: 10038.68 | I40: =H40 -> 10038.68 | J40: =I40 -> 10038.68 | K40: =J40 -> 10038.68 | L40: =K40 -> 10038.68 | M40: =L40 -> 10038.68
A41: Other Non-current Liabilities | B41: 4384.01 | C41: 3876.67 | D41: 3914.45 | E41: 3763.89 | F41: 3761.77 | G41: 12088.36 | H41: 11489.1 | I41: =H41 -> 11489.1 | J41: =I41 -> 11489.1 | K41: =J41 -> 11489.1 | L41: =K41 -> 11489.1 | M41: =L41 -> 11489.1
A42: Long Term Provisions | B42: 368.15 | C42: 424.71 | D42: 461.93 | E42: 517.05 | F42: 577.61 | G42: 643.11 | H42: 723.77 | I42: =H42*1.05 -> 759.9585 | J42: =I42*1.05 -> 797.95642 | K42: =J42*1.05 -> 837.85425 | L42: =K42*1.05 -> 879.74696 | M42: =L42*1.05 -> 923.73431
A43: Total Non-Current Liabilities | B43: 145884.69 | C43: 151104.34 | D43: 145398.33 | E43: 129905.12 | F43: 128850.57 | G43: 127779.82 | H43: 132109.5 | I43: =I39+I40+I41+I42 -> 126652.79 | J43: =J39+J40+J41+J42 -> 121472.54 | K43: =K39+K40+K41+K42 -> 116555.09 | L43: =L39+L40+L41+L42 -> 111887.51 | M43: =M39+M40+M41+M42 -> 107457.5
A45: Short Term Borrowings | B45: 4300 | C45: 3000 | D45: 13971.41 | E45: 20465.87 | F45: 14626.22 | G45: 18381.67 | H45: 21107.01 | I45: =H45*1.03 -> 21740.22 | J45: =I45*1.03 -> 22392.427 | K45: =J45*1.03 -> 23064.2 | L45: =K45*1.03 -> 23756.126 | M45: =L45*1.03 -> 24468.809
A46: Trade Payables | B46: 364.11 | C46: 225.72 | D46: 186.3 | E46: 266.14 | F46: 325.02 | G46: 354.07 | H46: 567.68 | I46: =H46*1.05 -> 596.064 | J46: =I46*1.05 -> 625.8672 | K46: =J46*1.05 -> 657.16056 | L46: =K46*1.05 -> 690.01859 | M46: =L46*1.05 -> 724.51952
A47: Other Current Liabilities | B47: 36206.47 | C47: 36015.18 | D47: 23854.42 | E47: 20126.85 | F47: 20688.45 | G47: 11414.02 | H47: 11052 | I47: =H47*0.95 -> 10499.4 | J47: =I47*0.95 -> 9974.43 | K47: =J47*0.95 -> 9475.7085 | L47: =K47*0.95 -> 9001.9231 | M47: =L47*0.95 -> 8551.8269
A48: Short Term Provisions | B48: 700.59 | C48: 764.73 | D48: 1261.39 | E48: 932.31 | F48: 816.01 | G48: 583.36 | H48: 769.49 | I48: =H48 -> 769.49 | J48: =I48 -> 769.49 | K48: =J48 -> 769.49 | L48: =K48 -> 769.49 | M48: =L48 -> 769.49
A49: Total Current Liabilities | B49: 41571.17 | C49: 40005.63 | D49: 39273.52 | E49: 41791.17 | F49: 36455.7 | G49: 30733.12 | H49: 33496.18 | I49: =I45+I46+I47+I48 -> 33605.174 | J49: =J45+J46+J47+J48 -> 33762.214 | K49: =K45+K46+K47+K48 -> 33966.559 | L49: =L45+L46+L47+L48 -> 34217.557 | M49: =M45+M46+M47+M48 -> 34514.646
...

Sheet PPE schedule 
A1: PPE SCHEDULE
B2: ACTUAL PERIOD | I2: FORECASTED PERIOD
A4: INR in Cr. | B4: 2019 Actual | C4: 2020 Actual | D4: 2021 Actual | E4: 2022 Actual | F4: 2023 Actual | G4: 2024 Actual | H4: 2025 Actual | I4: 2026 Forecast | J4: 2027 Forecast | K4: 2028 Forecast | L4: 2029 Forecast | M4: 2030 Forecast
A5: Revenues | B5: ='Financial Statement'!B9 -> 34119.12 | C5: ='Financial Statement'!C9 -> 36185.54 | D5: ='Financial Statement'!D9 -> 37665.65 | E5: ='Financial Statement'!E9 -> 39933.39 | F5: ='Financial Statement'!F9 -> 43343.05 | G5: ='Financial Statement'!G9 -> 42391.16 | H5: ='Financial Statement'!H9 -> 41431.49 | I5: ='Financial Statement'!I9 -> 43503.065 | ... M5: ='Financial Statement'!M9 -> 52878.247
A6: Opening PP&E (Net Block) | B6: =Assumptions!B48 -> 197438.06 | C6: =Assumptions!C48 -> 200236.06 | D6: =Assumptions!D48 -> 194915.03 | E6: =Assumptions!E48 -> 187107.75 | F6: =Assumptions!F48 -> 179976.76 | G6: =Assumptions!G48 -> 172372.68 | H6: =Assumptions!H48 -> 166033.9 | I6: =Assumptions!I48 -> 165203.73 | ... M6: =Assumptions!M48 -> 161924.35
A7: Capex (Capital Expenditure) | B7: ='Financial Statement'!B85 -> -19462.03 | C7: ='Financial Statement'!C85 -> -8006.12 | D7: ='Financial Statement'!D85 -> -6389.23 | E7: ='Financial Statement'!E85 -> -3645.32 | F7: ='Financial Statement'!F85 -> -3064.54 | G7: ='Financial Statement'!G85 -> -5517.74 | H7: ='Financial Statement'!H85 -> -5142.74 | I7: ='Financial Statement'!I85 -> -5399.877 | ... M7: ='Financial Statement'!M85 -> -6563.5842
A8: (% of revenues) | B8: =B7/B5 -> -0.57041418 | C8: =C7/C5 -> -0.22125191 | D8: =D7/D5 -> -0.16963015 | E8: =E7/E5 -> -0.091285012 | F8: =F7/F5 -> -0.0707043 | G8: =G7/G5 -> -0.13016252 | H8: =H7/H5 -> -0.12412636 | I8: 0.13 | J8: 0.13 | K8: 0.13 | L8: 0.13 | M8: 0.13
A9: Depreciation | B9: ='Financial Statement'!B17 -> 10200.67 | C9: ='Financial Statement'!C17 -> 11073.18 | D9: ='Financial Statement'!D17 -> 11711.68 | E9: ='Financial Statement'!E17 -> 12550.58 | F9: ='Financial Statement'!F17 -> 12939.88 | G9: ='Financial Statement'!G17 -> 12558.19 | H9: ='Financial Statement'!H17 -> 12352.23 | I9: ='Financial Statement'!I17 -> 12290.469 | ... M9: ='Financial Statement'!M17 -> 12046.497
A10: (Depreciation Rate %) | B10: =B9/(B6+(B7*0.5)) -> 0.054343565 | C10: =C9/(C6+(C7*0.5)) -> 0.056428735 | D10: =D9/(D6+(D7*0.5)) -> 0.061087287 | E10: =E9/(E6+(E7*0.5)) -> 0.067736589 | F10: =F9/(F6+(F7*0.5)) -> 0.072514876 | G10: =G9/(G6+(G7*0.5)) -> 0.074039903 | H10: =H9/(H6+(H7*0.5)) -> 0.075566125 | I10: =I9/(I6+(I7*0.5)) -> 0.07563189 | ... M10: =M9/(M6+(M7*0.5)) -> 0.075934836
A11: Ending PP&E (Net Block) | B11: 197438.06 | C11: 200236.06 | D11: 194915.03 | E11: 187107.75 | F11: 179976.76 | G11: 172372.68 | H11: 166033.9 | I11: =I6+I7-I9 -> 147513.38 | J11: =J6+J7-J9 -> 146478.82 | K11: =K6+K7-K9 -> 145434.59 | L11: =L6+L7-L9 -> 144379.98 | M11: =M6+M7-M9 -> 143314.27
A13: NOTES & KEY ASSUMPTIONS (Energy Sector Adjustments):
A14: 1. PP&E represents PowerGrid's high-voltage transmission infrastructure (lines, substations, switchyards)
A15: 2. Capex forecast at 13% of revenues — higher than steel (5%) reflecting regulated utility's ongoing network expansion
A16: 3. Depreciation Rate at 7% follows CERC (Central Electricity Regulatory Commission) norms for transmission assets
A17: 4. No raw-material inventory or COGS in PP&E roll — replaced by transmission tariff revenue as the primary driver
A18: 5. Forecast Revenue growth at 8% p.a. (Base Case); update row 4 Forecast assumptions to switch scenarios
A19: 6. Capex % of Revenue (Row 7, blue cells) and Depreciation Rate % (Row 9, blue cells) are editable assumptions
A20: 7. Ending PP&E = Opening PP&E + Capex − Depreciation (standard PPE roll-forward)

Sheet WACC
A1: Weighted Average Cost of Capital | I1: Label | J1: Value
I2: % of Debt | J2: =B8 -> 0.58681155
I3: % of Equity | J3: =B9 -> 0.41318845
A4: Capital Structure
A5: Total Debt | B5: 130964.96
A6: Total Equity | B6: ='Financial Statement'!H37 -> 92215.65
A7: Total Mix | B7: =B5+B6 -> 223180.61
A8: % of Debt | B8: =B5/B7 -> 0.58681155
A9: % of Equity | B9: =B6/B7 -> 0.41318845
A10: Debt to Equity | B10: =B5/B6 -> 1.4202032
A14: Cost of Equity (CAPM) | D14: Cost of Debt
A15: Risk Free Rate (Rf) | B15: 0.071 | D15: Source | G15: Cost
A16: Beta (β) | B16: 0.65 | D16: Cost of Debt (Pre-tax)* | G16: 0.079
A17: Market Risk Premium (MRP) | B17: 0.0685 | D17: Tax Rate | G17: 0.25
A18: Cost of Equity (Ke) | B18: =B15+B16*B17 -> 0.115525 | D18: Cost of Debt After Tax (Kd) | G18: =G16*(1-G17) -> 0.05925
A21: WACC
A22: Source | C22: Weight | E22: Cost | G22: Weighted Cost
A23: Debt | C23: =B8 -> 0.58681155 | E23: =G18 -> 0.05925 | G23: =C23*E23 -> 0.034768584
A24: Equity | C24: =B9 -> 0.41318845 | E24: =B18 -> 0.115525 | G24: =C24*E24 -> 0.047733596
A25: WACC | G25: =G23+G24 -> 0.08250218
A27: * Cost of Debt (Pre-tax) = FY2025 Interest Expense (₹9,479 Cr) / Average Total Debt (~₹1,20,000 Cr) ≈ 7.90%
A28: Beta (0.65) reflects PowerGrid's status as a CPSU regulated utility — lower risk than steel (1.18)
A29: Rf = 10-year GoI bond yield (~7.10% as of FY2025); MRP = India Equity Risk Premium (6.85%)
A30: Cost of Equity = Rf + β × MRP (CAPM) | Cost of Debt After Tax = Pre-tax Kd × (1 − Tax Rate)
A31: WACC = (Weight of Debt × After-tax Kd) + (Weight of Equity × Ke)
A32: All data sourced from PowerGrid FY2025 Annual Report Balance Sheet & Income Statement

Sheet DCF valuation
A1: DCF VALUATION – POWER GRID CORPORATION OF INDIA LTD | K1: Label | L1: Value
K2: CMP | L2: =C9 -> 330
A3: Assumptions / Base | K3: Upside Potential | L3: =C33 -> 640.58711
A4: Tax Rate | C4: =WACC!G17 -> 0.25 | K4: Fair Value | L4: =J24 -> Intrinsic Value of Share
A5: Discount Rate (WACC) | C5: =WACC!G25 -> 0.08250218
A6: Perpetual Growth Rate | C6: 5.50%
A7: Valuation Date | C7: 01/04/2025
A8: Last Fiscal Year End | C8: 31/03/2025
A9: Current Market Price (₹) | C9: 330
A10: Total Shares Outstanding (in Cr.) | C10: 930.06
A11: Debt (in Cr.) | C11: 130964.96
A12: Cash (in Cr.) | C12: 6419.4
H14: INR Cr.
A15: Discounted Cash Flows | J15: Intrinsic Value
A16: Year > | B16: 1 | C16: 2 | D16: 3 | E16: 4 | F16: 5 | G16: Perpetuity Growth Terminal Value | J16: PV of Cash Flows | K16: =SUM(B28:F28) -> 125461.86
A17: Particulars | B17: 2026 | C17: 2027 | D17: 2028 | E17: 2029 | F17: 2030 | J17: Continuing Value | K17: =G24 -> 1313605.2
A18: EBIT | B18: ='Financial Statement'!I18 -> 30174.198 | C18: ='Financial Statement'!J18 -> 32350.04 | D18: ='Financial Statement'!K18 -> 34631.326 | E18: ='Financial Statement'!L18 -> 37023.356 | F18: ='Financial Statement'!M18 -> 39531.699 | J18: PV of Continuing Value | K18: =G28 -> 883732.8
A19: Tax Rate | B19: =C4 -> 0.25 | C19: =C4 -> 0.25 | D19: =C4 -> 0.25 | E19: =C4 -> 0.25 | F19: =C4 -> 0.25 | J19: Enterprise Value (in Cr.) | K19: =K16+K18 -> 1009194.7
A20: NOPAT (EBIT × (1 - Tax Rate)) | B20: =B18*(1-C4) -> 22630.648 | C20: =C18*(1-C4) -> 24262.53 | D20: =D18*(1-C4) -> 25973.494 | E20: =E18*(1-C4) -> 27767.517 | F20: =F18*(1-C4) -> 29648.774 | J20: Less: Debt (in Cr.) | K20: =C11 -> 130964.96
A21: Add: Depreciation | B21: ='Financial Statement'!I17 -> 12290.469 | C21: ='Financial Statement'!J17 -> 12229.017 | D21: ='Financial Statement'!K17 -> 12167.871 | E21: ='Financial Statement'!L17 -> 12107.032 | F21: ='Financial Statement'!M17 -> 12046.497 | J21: Add: Cash (in Cr.) | K21: =C12 -> 6419.4
A22: Less: Capex | B22: 5554.16 | C22: 5998.49 | D22: 6478.37 | E22: 6996.64 | F22: 7556.37 | J22: Equity Value (in Cr.) | K22: =K19-K20+K21 -> 884649.1
A23: Less: Net Changes in Working Capital | B23: ='Financial Statement'!I81 -> -115.3774 | C23: ='Financial Statement'!J81 -> -113.06303 | D23: ='Financial Statement'!K81 -> -110.4992 | E23: ='Financial Statement'!L81 -> -107.70776 | F23: ='Financial Statement'!M81 -> -104.70822 | J23: No. of Shares (in Cr.) | K23: =C10 -> 930.06
